Workbook
Name DataChannelCountSetting: Settings!$C$8
Name DataDelaySetting: Settings!$C$4
Name DataOrientationSetting: Settings!$C$10
Name DataRowCountSetting: Settings!$C$6
Name Manifest_BaudRate: Manifest!$I$9
Name Manifest_DataInterval: Manifest!$I$7
Name Manifest_Generated: Manifest!$K$5
Name Manifest_Id: Manifest!$I$5:$J$5
Name Manifest_Schema: Manifest!$L$1
Name Threshold: 'CH2 DStream'!$AF$24
Name Threshold: DStream!$S$24
Name Threshold: Sheet1!$S$24
Name Threshold2: 'CH2 DStream'!$AL$24

Sheet DStream
A1: Serial Data | B1: colon 1 | C1: colon 2 | D1: colon 3 | E1: colon 4 | F1: Start time | G1: Voltage | H1: End time | I1: Rising Through Threshold | J1: Last | K1: Period
A2: Start:8:4.18: | B2: =FIND(":",$A2,1) -> 6 | C2: =FIND(":",$A2,B2+1) -> 8 | D2: =FIND(":",$A2,C2+1) -> 13 | E2: =FIND(":",$A2,D2+1) -> #VALUE! | F2: ='Data In'!C8 -> 0.51 | G2: ='Data In'!D8 -> a | H2: =_xlfn.NUMBERVALUE(MID($A2,E2+1,1000)) -> #VALUE! | I2: =AND(G1<Threshold,G2>Threshold) -> #REF! | K2: =IF(AND(Table15[[#This Row],[Rising Through Threshold]],J1>0),J2-J1,"") -> #REF!
A3: Start:216:4.09: | B3: =FIND(":",$A3,1) -> 6 | C3: =FIND(":",$A3,B3+1) -> 10 | D3: =FIND(":",$A3,C3+1) -> 15 | E3: =FIND(":",$A3,D3+1) -> #VALUE! | F3: ='Data In'!C9 -> 0.63 | G3: ='Data In'!D9 -> a | H3: =_xlfn.NUMBERVALUE(MID($A3,E3+1,1000)) -> #VALUE! | I3: =AND(G2<Threshold,G3>Threshold) -> #REF! | J3: =IF(Table15[[#This Row],[Rising Through Threshold]],Table15[[#This Row],[Start time]],J2) -> #REF! | K3: =IF(AND(Table15[[#This Row],[Rising Through Threshold]],J2>0),J3-J2,"") -> #REF!
A4: Start:328:3.92: | B4: =FIND(":",$A4,1) -> 6 | C4: =FIND(":",$A4,B4+1) -> 10 | D4: =FIND(":",$A4,C4+1) -> 15 | E4: =FIND(":",$A4,D4+1) -> #VALUE! | F4: ='Data In'!C10 -> 0.8 | G4: ='Data In'!D10 -> a | H4: =_xlfn.NUMBERVALUE(MID($A4,E4+1,1000)) -> #VALUE! | I4: =AND(G3<Threshold,G4>Threshold) -> #REF! | J4: =IF(Table15[[#This Row],[Rising Through Threshold]],Table15[[#This Row],[Start time]],J3) -> #REF! | K4: =IF(AND(Table15[[#This Row],[Rising Through Threshold]],J3>0),J4-J3,"") -> #REF!
A5: Start:440:3.68: | B5: =FIND(":",$A5,1) -> 6 | C5: =FIND(":",$A5,B5+1) -> 10 | D5: =FIND(":",$A5,C5+1) -> 15 | E5: =FIND(":",$A5,D5+1) -> #VALUE! | F5: ='Data In'!C11 -> 1.06 | G5: ='Data In'!D11 -> a | H5: =_xlfn.NUMBERVALUE(MID($A5,E5+1,1000)) -> #VALUE! | I5: =AND(G4<Threshold,G5>Threshold) -> #REF! | J5: =IF(Table15[[#This Row],[Rising Through Threshold]],Table15[[#This Row],[Start time]],J4) -> #REF! | K5: =IF(AND(Table15[[#This Row],[Rising Through Threshold]],J4>0),J5-J4,"") -> #REF!
A6: Start:552:3.39: | B6: =FIND(":",$A6,1) -> 6 | C6: =FIND(":",$A6,B6+1) -> 10 | D6: =FIND(":",$A6,C6+1) -> 15 | E6: =FIND(":",$A6,D6+1) -> #VALUE! | F6: ='Data In'!C12 -> 1.31 | G6: ='Data In'!D12 -> a | H6: =_xlfn.NUMBERVALUE(MID($A6,E6+1,1000)) -> #VALUE! | I6: =AND(G5<Threshold,G6>Threshold) -> #REF! | J6: =IF(Table15[[#This Row],[Rising Through Threshold]],Table15[[#This Row],[Start time]],J5) -> #REF! | K6: =IF(AND(Table15[[#This Row],[Rising Through Threshold]],J5>0),J6-J5,"") -> #REF!
A7: Start:664:3.06: | B7: =FIND(":",$A7,1) -> 6 | C7: =FIND(":",$A7,B7+1) -> 10 | D7: =FIND(":",$A7,C7+1) -> 15 | E7: =FIND(":",$A7,D7+1) -> #VALUE! | F7: ='Data In'!C13 -> 1.59 | G7: ='Data In'!D13 -> a | H7: =_xlfn.NUMBERVALUE(MID($A7,E7+1,1000)) -> #VALUE! | I7: =AND(G6<Threshold,G7>Threshold) -> #REF! | J7: =IF(Table15[[#This Row],[Rising Through Threshold]],Table15[[#This Row],[Start time]],J6) -> #REF! | K7: =IF(AND(Table15[[#This Row],[Rising Through Threshold]],J6>0),J7-J6,"") -> #REF!
A8: Start:776:2.71: | B8: =FIND(":",$A8,1) -> 6 | C8: =FIND(":",$A8,B8+1) -> 10 | D8: =FIND(":",$A8,C8+1) -> 15 | E8: =FIND(":",$A8,D8+1) -> #VALUE! | F8: ='Data In'!C14 -> 1.84 | G8: ='Data In'!D14 -> a | H8: =_xlfn.NUMBERVALUE(MID($A8,E8+1,1000)) -> #VALUE! | I8: =AND(G7<Threshold,G8>Threshold) -> #REF! | J8: =IF(Table15[[#This Row],[Rising Through Threshold]],Table15[[#This Row],[Start time]],J7) -> #REF! | K8: =IF(AND(Table15[[#This Row],[Rising Through Threshold]],J7>0),J8-J7,"") -> #REF!
A9: Start:888:2.34: | B9: =FIND(":",$A9,1) -> 6 | C9: =FIND(":",$A9,B9+1) -> 10 | D9: =FIND(":",$A9,C9+1) -> 15 | E9: =FIND(":",$A9,D9+1) -> #VALUE! | F9: ='Data In'!C15 -> 2.1 | G9: ='Data In'!D15 -> a | H9: =_xlfn.NUMBERVALUE(MID($A9,E9+1,1000)) -> #VALUE! | I9: =AND(G8<Threshold,G9>Threshold) -> #REF! | J9: =IF(Table15[[#This Row],[Rising Through Threshold]],Table15[[#This Row],[Start time]],J8) -> #REF! | K9: =IF(AND(Table15[[#This Row],[Rising Through Threshold]],J8>0),J9-J8,"") -> #REF!
A10: Start:1000:1.97: | B10: =FIND(":",$A10,1) -> 6 | C10: =FIND(":",$A10,B10+1) -> 11 | D10: =FIND(":",$A10,C10+1) -> 16 | E10: =FIND(":",$A10,D10+1) -> #VALUE! | F10: ='Data In'!C16 -> 2.31 | G10: ='Data In'!D16 -> a | H10: =_xlfn.NUMBERVALUE(MID($A10,E10+1,1000)) -> #VALUE! | I10: =AND(G9<Threshold,G10>Threshold) -> #REF! | J10: =IF(Table15[[#This Row],[Rising Through Threshold]],Table15[[#This Row],[Start time]],J9) -> #REF! | K10: =IF(AND(Table15[[#This Row],[Rising Through Threshold]],J9>0),J10-J9,"") -> #REF!
A11: Start:1112:1.63: | B11: =FIND(":",$A11,1) -> 6 | C11: =FIND(":",$A11,B11+1) -> 11 | D11: =FIND(":",$A11,C11+1) -> 16 | E11: =FIND(":",$A11,D11+1) -> #VALUE! | F11: ='Data In'!C17 -> 2.53 | G11: ='Data In'!D17 -> a | H11: =_xlfn.NUMBERVALUE(MID($A11,E11+1,1000)) -> #VALUE! | I11: =AND(G10<Threshold,G11>Threshold) -> #REF! | J11: =IF(Table15[[#This Row],[Rising Through Threshold]],Table15[[#This Row],[Start time]],J10) -> #REF! | K11: =IF(AND(Table15[[#This Row],[Rising Through Threshold]],J10>0),J11-J10,"") -> #REF!
A12: Start:1224:1.32: | B12: =FIND(":",$A12,1) -> 6 | C12: =FIND(":",$A12,B12+1) -> 11 | D12: =FIND(":",$A12,C12+1) -> 16 | E12: =FIND(":",$A12,D12+1) -> #VALUE! | F12: ='Data In'!C18 -> 2.71 | G12: ='Data In'!D18 -> a | H12: =_xlfn.NUMBERVALUE(MID($A12,E12+1,1000)) -> #VALUE! | I12: =AND(G11<Threshold,G12>Threshold) -> #REF! | J12: =IF(Table15[[#This Row],[Rising Through Threshold]],Table15[[#This Row],[Start time]],J11) -> #REF! | K12: =IF(AND(Table15[[#This Row],[Rising Through Threshold]],J11>0),J12-J11,"") -> #REF!
A13: Start:1336:1.09: | B13: =FIND(":",$A13,1) -> 6 | C13: =FIND(":",$A13,B13+1) -> 11 | D13: =FIND(":",$A13,C13+1) -> 16 | E13: =FIND(":",$A13,D13+1) -> #VALUE! | F13: ='Data In'!C19 -> 2.88 | G13: ='Data In'!D19 -> a | H13: =_xlfn.NUMBERVALUE(MID($A13,E13+1,1000)) -> #VALUE! | I13: =AND(G12<Threshold,G13>Threshold) -> #REF! | J13: =IF(Table15[[#This Row],[Rising Through Threshold]],Table15[[#This Row],[Start time]],J12) -> #REF! | K13: =IF(AND(Table15[[#This Row],[Rising Through Threshold]],J12>0),J13-J12,"") -> #REF!
A14: Start:1448:0.92: | B14: =FIND(":",$A14,1) -> 6 | C14: =FIND(":",$A14,B14+1) -> 11 | D14: =FIND(":",$A14,C14+1) -> 16 | E14: =FIND(":",$A14,D14+1) -> #VALUE! | F14: ='Data In'!C20 -> 3.04 | G14: ='Data In'!D20 -> a | H14: =_xlfn.NUMBERVALUE(MID($A14,E14+1,1000)) -> #VALUE! | I14: =AND(G13<Threshold,G14>Threshold) -> #REF! | J14: =IF(Table15[[#This Row],[Rising Through Threshold]],Table15[[#This Row],[Start time]],J13) -> #REF! | K14: =IF(AND(Table15[[#This Row],[Rising Through Threshold]],J13>0),J14-J13,"") -> #REF!
... A23: Start:2456:2.95: | B23: =FIND(":",$A23,1) -> 6 | C23: =FIND(":",$A23,B23+1) -> 11 | D23: =FIND(":",$A23,C23+1) -> 16 | E23: =FIND(":",$A23,D23+1) -> #VALUE! | F23: ='Data In'!C29 -> 3.63 | G23: ='Data In'!D29 -> a | H23: =_xlfn.NUMBERVALUE(MID($A23,E23+1,1000)) -> #VALUE! | I23: =AND(G22<Threshold,G23>Threshold) -> #REF! | J23: =IF(Table15[[#This Row],[Rising Through Threshold]],Table15[[#This Row],[Start time]],J22) -> #REF! | K23: =IF(AND(Table15[[#This Row],[Rising Through Threshold]],J22>0),J23-J22,"") -> #REF!
A24: Start:2568:3.33: | B24: =FIND(":",$A24,1) -> 6 | C24: =FIND(":",$A24,B24+1) -> 11 | D24: =FIND(":",$A24,C24+1) -> 16 | E24: =FIND(":",$A24,D24+1) -> #VALUE! | F24: ='Data In'!C30 -> 3.37 | G24: ='Data In'!D30 -> a | H24: =_xlfn.NUMBERVALUE(MID($A24,E24+1,1000)) -> #VALUE! | I24: =AND(G23<Threshold,G24>Threshold) -> #REF! | J24: =IF(Table15[[#This Row],[Rising Through Threshold]],Table15[[#This Row],[Start time]],J23) -> #REF! | K24: =IF(AND(Table15[[#This Row],[Rising Through Threshold]],J23>0),J24-J23,"") -> #REF! | N24: Max | O24: =MAX(Table15[Voltage]) -> #REF! | R24: Threshold | S24: =O27 -> #REF!
A25: Start:2680:3.66: | B25: =FIND(":",$A25,1) -> 6 | C25: =FIND(":",$A25,B25+1) -> 11 | D25: =FIND(":",$A25,C25+1) -> 16 | E25: =FIND(":",$A25,D25+1) -> #VALUE! | F25: ='Data In'!C31 -> 2.94 | G25: ='Data In'!D31 -> a | H25: =_xlfn.NUMBERVALUE(MID($A25,E25+1,1000)) -> #VALUE! | I25: =AND(G24<Threshold,G25>Threshold) -> #REF! | J25: =IF(Table15[[#This Row],[Rising Through Threshold]],Table15[[#This Row],[Start time]],J24) -> #REF! | K25: =IF(AND(Table15[[#This Row],[Rising Through Threshold]],J24>0),J25-J24,"") -> #REF! | N25: Min | O25: =MIN(Table15[Voltage]) -> #REF! | R25: Period | S25: =Table15[[#Totals],[Period]] -> #REF!
A26: Start:2792:3.91: | B26: =FIND(":",$A26,1) -> 6 | C26: =FIND(":",$A26,B26+1) -> 11 | D26: =FIND(":",$A26,C26+1) -> 16 | E26: =FIND(":",$A26,D26+1) -> #VALUE! | F26: ='Data In'!C32 -> 2.33 | G26: ='Data In'!D32 -> a | H26: =_xlfn.NUMBERVALUE(MID($A26,E26+1,1000)) -> #VALUE! | I26: =AND(G25<Threshold,G26>Threshold) -> #REF! | J26: =IF(Table15[[#This Row],[Rising Through Threshold]],Table15[[#This Row],[Start time]],J25) -> #REF! | K26: =IF(AND(Table15[[#This Row],[Rising Through Threshold]],J25>0),J26-J25,"") -> #REF! | N26: Peak to peak | O26: =O24-O25 -> #REF! | R26: Frequency | S26: =1/(S25/1000000) -> #REF!
A27: Start:2904:4.09: | B27: =FIND(":",$A27,1) -> 6 | C27: =FIND(":",$A27,B27+1) -> 11 | D27: =FIND(":",$A27,C27+1) -> 16 | E27: =FIND(":",$A27,D27+1) -> #VALUE! | F27: ='Data In'!C33 -> 1.61 | G27: ='Data In'!D33 -> a | H27: =_xlfn.NUMBERVALUE(MID($A27,E27+1,1000)) -> #VALUE! | I27: =AND(G26<Threshold,G27>Threshold) -> #REF! | J27: =IF(Table15[[#This Row],[Rising Through Threshold]],Table15[[#This Row],[Start time]],J26) -> #REF! | K27: =IF(AND(Table15[[#This Row],[Rising Through Threshold]],J26>0),J27-J26,"") -> #REF! | N27: Average | O27: =Table15[[#Totals],[Voltage]] -> #REF!
A28: Start:3016:4.18: | B28: =FIND(":",$A28,1) -> 6 | C28: =FIND(":",$A28,B28+1) -> 11 | D28: =FIND(":",$A28,C28+1) -> 16 | E28: =FIND(":",$A28,D28+1) -> #VALUE! | F28: ='Data In'!C34 -> 0.9 | G28: ='Data In'!D34 -> a | H28: =_xlfn.NUMBERVALUE(MID($A28,E28+1,1000)) -> #VALUE! | I28: =AND(G27<Threshold,G28>Threshold) -> #REF! | J28: =IF(Table15[[#This Row],[Rising Through Threshold]],Table15[[#This Row],[Start time]],J27) -> #REF! | K28: =IF(AND(Table15[[#This Row],[Rising Through Threshold]],J27>0),J28-J27,"") -> #REF!
A29: Start:3128:4.20: | B29: =FIND(":",$A29,1) -> 6 | C29: =FIND(":",$A29,B29+1) -> 11 | D29: =FIND(":",$A29,C29+1) -> 16 | E29: =FIND(":",$A29,D29+1) -> #VALUE! | F29: ='Data In'!C35 -> 0.43 | G29: ='Data In'!D35 -> a | H29: =_xlfn.NUMBERVALUE(MID($A29,E29+1,1000)) -> #VALUE! | I29: =AND(G28<Threshold,G29>Threshold) -> #REF! | J29: =IF(Table15[[#This Row],[Rising Through Threshold]],Table15[[#This Row],[Start time]],J28) -> #REF! | K29: =IF(AND(Table15[[#This Row],[Rising Through Threshold]],J28>0),J29-J28,"") -> #REF!
A30: Start:3240:4.15: | B30: =FIND(":",$A30,1) -> 6 | C30: =FIND(":",$A30,B30+1) -> 11 | D30: =FIND(":",$A30,C30+1) -> 16 | E30: =FIND(":",$A30,D30+1) -> #VALUE! | F30: ='Data In'!C36 -> 0.45 | G30: ='Data In'!D36 -> a | H30: =_xlfn.NUMBERVALUE(MID($A30,E30+1,1000)) -> #VALUE! | I30: =AND(G29<Threshold,G30>Threshold) -> #REF! | J30: =IF(Table15[[#This Row],[Rising Through Threshold]],Table15[[#This Row],[Start time]],J29) -> #REF! | K30: =IF(AND(Table15[[#This Row],[Rising Through Threshold]],J29>0),J30-J29,"") -> #REF!
A31: Start:3352:4.02: | B31: =FIND(":",$A31,1) -> 6 | C31: =FIND(":",$A31,B31+1) -> 11 | D31: =FIND(":",$A31,C31+1) -> 16 | E31: =FIND(":",$A31,D31+1) -> #VALUE! | F31: ='Data In'!C37 -> 0.47 | G31: ='Data In'!D37 -> a | H31: =_xlfn.NUMBERVALUE(MID($A31,E31+1,1000)) -> #VALUE! | I31: =AND(G30<Threshold,G31>Threshold) -> #REF! | J31: =IF(Table15[[#This Row],[Rising Through Threshold]],Table15[[#This Row],[Start time]],J30) -> #REF! | K31: =IF(AND(Table15[[#This Row],[Rising Through Threshold]],J30>0),J31-J30,"") -> #REF!
A32: Start:3464:3.82: | B32: =FIND(":",$A32,1) -> 6 | C32: =FIND(":",$A32,B32+1) -> 11 | D32: =FIND(":",$A32,C32+1) -> 16 | E32: =FIND(":",$A32,D32+1) -> #VALUE! | F32: ='Data In'!C38 -> 0.57 | G32: ='Data In'!D38 -> a | H32: =_xlfn.NUMBERVALUE(MID($A32,E32+1,1000)) -> #VALUE! | I32: =AND(G31<Threshold,G32>Threshold) -> #REF! | J32: =IF(Table15[[#This Row],[Rising Through Threshold]],Table15[[#This Row],[Start time]],J31) -> #REF! | K32: =IF(AND(Table15[[#This Row],[Rising Through Threshold]],J31>0),J32-J31,"") -> #REF!
A33: Start:3576:3.56: | B33: =FIND(":",$A33,1) -> 6 | C33: =FIND(":",$A33,B33+1) -> 11 | D33: =FIND(":",$A33,C33+1) -> 16 | E33: =FIND(":",$A33,D33+1) -> #VALUE! | F33: ='Data In'!C39 -> 0.73 | G33: ='Data In'!D39 -> a | H33: =_xlfn.NUMBERVALUE(MID($A33,E33+1,1000)) -> #VALUE! | I33: =AND(G32<Threshold,G33>Threshold) -> #REF! | J33: =IF(Table15[[#This Row],[Rising Through Threshold]],Table15[[#This Row],[Start time]],J32) -> #REF! | K33: =IF(AND(Table15[[#This Row],[Rising Through Threshold]],J32>0),J33-J32,"") -> #REF!
A34: Start:3688:3.25: | B34: =FIND(":",$A34,1) -> 6 | C34: =FIND(":",$A34,B34+1) -> 11 | D34: =FIND(":",$A34,C34+1) -> 16 | E34: =FIND(":",$A34,D34+1) -> #VALUE! | F34: ='Data In'!C40 -> 0.96 | G34: ='Data In'!D40 -> a | H34: =_xlfn.NUMBERVALUE(MID($A34,E34+1,1000)) -> #VALUE! | I34: =AND(G33<Threshold,G34>Threshold) -> #REF! | J34: =IF(Table15[[#This Row],[Rising Through Threshold]],Table15[[#This Row],[Start time]],J33) -> #REF! | K34: =IF(AND(Table15[[#This Row],[Rising Through Threshold]],J33>0),J34-J33,"") -> #REF!
A35: Start:3800:2.91: | B35: =FIND(":",$A35,1) -> 6 | C35: =FIND(":",$A35,B35+1) -> 11 | D35: =FIND(":",$A35,C35+1) -> 16 | E35: =FIND(":",$A35,D35+1) -> #VALUE! | F35: ='Data In'!C41 -> 1.22 | G35: ='Data In'!D41 -> a | H35: =_xlfn.NUMBERVALUE(MID($A35,E35+1,1000)) -> #VALUE! | I35: =AND(G34<Threshold,G35>Threshold) -> #REF! | J35: =IF(Table15[[#This Row],[Rising Through Threshold]],Table15[[#This Row],[Start time]],J34) -> #REF! | K35: =IF(AND(Table15[[#This Row],[Rising Through Threshold]],J34>0),J35-J34,"") -> #REF!
A36: Start:3912:2.54: | B36: =FIND(":",$A36,1) -> 6 | C36: =FIND(":",$A36,B36+1) -> 11 | D36: =FIND(":",$A36,C36+1) -> 16 | E36: =FIND(":",$A36,D36+1) -> #VALUE! | F36: ='Data In'!C42 -> 1.49 | G36: ='Data In'!D42 -> a | H36: =_xlfn.NUMBERVALUE(MID($A36,E36+1,1000)) -> #VALUE! | I36: =AND(G35<Threshold,G36>Threshold) -> #REF! | J36: =IF(Table15[[#This Row],[Rising Through Threshold]],Table15[[#This Row],[Start time]],J35) -> #REF! | K36: =IF(AND(Table15[[#This Row],[Rising Through Threshold]],J35>0),J36-J35,"") -> #REF!
A37: Start:4024:2.17: | B37: =FIND(":",$A37,1) -> 6 | C37: =FIND(":",$A37,B37+1) -> 11 | D37: =FIND(":",$A37,C37+1) -> 16 | E37: =FIND(":",$A37,D37+1) -> #VALUE! | F37: ='Data In'!C43 -> 1.75 | G37: ='Data In'!D43 -> a | H37: =_xlfn.NUMBERVALUE(MID($A37,E37+1,1000)) -> #VALUE! | I37: =AND(G36<Threshold,G37>Threshold) -> #REF! | J37: =IF(Table15[[#This Row],[Rising Through Threshold]],Table15[[#This Row],[Start time]],J36) -> #REF! | K37: =IF(AND(Table15[[#This Row],[Rising Through Threshold]],J36>0),J37-J36,"") -> #REF!
A38: Start:4136:1.81: | B38: =FIND(":",$A38,1) -> 6 | C38: =FIND(":",$A38,B38+1) -> 11 | D38: =FIND(":",$A38,C38+1) -> 16 | E38: =FIND(":",$A38,D38+1) -> #VALUE! | F38: ='Data In'!C44 -> 2 | G38: ='Data In'!D44 -> a | H38: =_xlfn.NUMBERVALUE(MID($A38,E38+1,1000)) -> #VALUE! | I38: =AND(G37<Threshold,G38>Threshold) -> #REF! | J38: =IF(Table15[[#This Row],[Rising Through Threshold]],Table15[[#This Row],[Start time]],J37) -> #REF! | K38: =IF(AND(Table15[[#This Row],[Rising Through Threshold]],J37>0),J38-J37,"") -> #REF!
A39: Start:4248:1.49: | B39: =FIND(":",$A39,1) -> 6 | C39: =FIND(":",$A39,B39+1) -> 11 | D39: =FIND(":",$A39,C39+1) -> 16 | E39: =FIND(":",$A39,D39+1) -> #VALUE! | F39: ='Data In'!C45 -> 2.24 | G39: ='Data In'!D45 -> a | H39: =_xlfn.NUMBERVALUE(MID($A39,E39+1,1000)) -> #VALUE! | I39: =AND(G38<Threshold,G39>Threshold) -> #REF! | J39: =IF(Table15[[#This Row],[Rising Through Threshold]],Table15[[#This Row],[Start time]],J38) -> #REF! | K39: =IF(AND(Table15[[#This Row],[Rising Through Threshold]],J38>0),J39-J38,"") -> #REF!
... A201: Start:22392:2.65: | B201: =FIND(":",$A201,1) -> 6 | C201: =FIND(":",$A201,B201+1) -> 12 | D201: =FIND(":",$A201,C201+1) -> 17 | E201: =FIND(":",$A201,D201+1) -> #VALUE! | F201: ='Data In'!C207 -> 2.84 | G201: ='Data In'!D207 -> a | H201: =_xlfn.NUMBERVALUE(MID($A201,E201+1,1000)) -> #VALUE! | I201: =AND(G200<Threshold,G201>Threshold) -> #REF! | J201: =IF(Table15[[#This Row],[Rising Through Threshold]],Table15[[#This Row],[Start time]],J200) -> #REF! | K201: =IF(AND(Table15[[#This Row],[Rising Through Threshold]],J200>0),J201-J200,"") -> #REF!
A202: Start:22504:2.28: | B202: =FIND(":",$A202,1) -> 6 | C202: =FIND(":",$A202,B202+1) -> 12 | D202: =FIND(":",$A202,C202+1) -> 17 | E202: =FIND(":",$A202,D202+1) -> #VALUE! | F202: ='Data In'!#REF! -> #REF! | G202: ='Data In'!#REF! -> #REF! | H202: =_xlfn.NUMBERVALUE(MID($A202,E202+1,1000)) -> #VALUE! | I202: =AND(G201<Threshold,G202>Threshold) -> #REF! | J202: =IF(Table15[[#This Row],[Rising Through Threshold]],Table15[[#This Row],[Start time]],J201) -> #REF! | K202: =IF(AND(Table15[[#This Row],[Rising Through Threshold]],J201>0),J202-J201,"") -> #REF!
A203: Start:22616:1.92: | B203: =FIND(":",$A203,1) -> 6 | C203: =FIND(":",$A203,B203+1) -> 12 | D203: =FIND(":",$A203,C203+1) -> 17 | E203: =FIND(":",$A203,D203+1) -> #VALUE! | F203: ='Data In'!#REF! -> #REF! | G203: ='Data In'!#REF! -> #REF! | H203: =_xlfn.NUMBERVALUE(MID($A203,E203+1,1000)) -> #VALUE! | I203: =AND(G202<Threshold,G203>Threshold) -> #REF! | J203: =IF(Table15[[#This Row],[Rising Through Threshold]],Table15[[#This Row],[Start time]],J202) -> #REF! | K203: =IF(AND(Table15[[#This Row],[Rising Through Threshold]],J202>0),J203-J202,"") -> #REF!
A204: Start:22728:1.58: | B204: =FIND(":",$A204,1) -> 6 | C204: =FIND(":",$A204,B204+1) -> 12 | D204: =FIND(":",$A204,C204+1) -> 17 | E204: =FIND(":",$A204,D204+1) -> #VALUE! | F204: ='Data In'!#REF! -> #REF! | G204: ='Data In'!#REF! -> #REF! | H204: =_xlfn.NUMBERVALUE(MID($A204,E204+1,1000)) -> #VALUE! | I204: =AND(G203<Threshold,G204>Threshold) -> #REF! | J204: =IF(Table15[[#This Row],[Rising Through Threshold]],Table15[[#This Row],[Start time]],J203) -> #REF! | K204: =IF(AND(Table15[[#This Row],[Rising Through Threshold]],J203>0),J204-J203,"") -> #REF!
A205: Start:22840:1.29: | B205: =FIND(":",$A205,1) -> 6 | C205: =FIND(":",$A205,B205+1) -> 12 | D205: =FIND(":",$A205,C205+1) -> 17 | E205: =FIND(":",$A205,D205+1) -> #VALUE! | F205: ='Data In'!#REF! -> #REF! | G205: ='Data In'!#REF! -> #REF! | H205: =_xlfn.NUMBERVALUE(MID($A205,E205+1,1000)) -> #VALUE! | I205: =AND(G204<Threshold,G205>Threshold) -> #REF! | J205: =IF(Table15[[#This Row],[Rising Through Threshold]],Table15[[#This Row],[Start time]],J204) -> #REF! | K205: =IF(AND(Table15[[#This Row],[Rising Through Threshold]],J204>0),J205-J204,"") -> #REF!
A206: Start:22952:1.06: | B206: =FIND(":",$A206,1) -> 6 | C206: =FIND(":",$A206,B206+1) -> 12 | D206: =FIND(":",$A206,C206+1) -> 17 | E206: =FIND(":",$A206,D206+1) -> #VALUE! | F206: ='Data In'!#REF! -> #REF! | G206: ='Data In'!#REF! -> #REF! | H206: =_xlfn.NUMBERVALUE(MID($A206,E206+1,1000)) -> #VALUE! | I206: =AND(G205<Threshold,G206>Threshold) -> #REF! | J206: =IF(Table15[[#This Row],[Rising Through Threshold]],Table15[[#This Row],[Start time]],J205) -> #REF! | K206: =IF(AND(Table15[[#This Row],[Rising Through Threshold]],J205>0),J206-J205,"") -> #REF!
A207: Start:23064:0.90: | B207: =FIND(":",$A207,1) -> 6 | C207: =FIND(":",$A207,B207+1) -> 12 | D207: =FIND(":",$A207,C207+1) -> 17 | E207: =FIND(":",$A207,D207+1) -> #VALUE! | F207: ='Data In'!#REF! -> #REF! | G207: ='Data In'!#REF! -> #REF! | H207: =_xlfn.NUMBERVALUE(MID($A207,E207+1,1000)) -> #VALUE! | I207: =AND(G206<Threshold,G207>Threshold) -> #REF! | J207: =IF(Table15[[#This Row],[Rising Through Threshold]],Table15[[#This Row],[Start time]],J206) -> #REF! | K207: =IF(AND(Table15[[#This Row],[Rising Through Threshold]],J206>0),J207-J206,"") -> #REF!
A208: Start:23176:0.84: | B208: =FIND(":",$A208,1) -> 6 | C208: =FIND(":",$A208,B208+1) -> 12 | D208: =FIND(":",$A208,C208+1) -> 17 | E208: =FIND(":",$A208,D208+1) -> #VALUE! | F208: ='Data In'!#REF! -> #REF! | G208: ='Data In'!#REF! -> #REF! | H208: =_xlfn.NUMBERVALUE(MID($A208,E208+1,1000)) -> #VALUE! | I208: =AND(G207<Threshold,G208>Threshold) -> #REF! | J208: =IF(Table15[[#This Row],[Rising Through Threshold]],Table15[[#This Row],[Start time]],J207) -> #REF! | K208: =IF(AND(Table15[[#This Row],[Rising Through Threshold]],J207>0),J208-J207,"") -> #REF!
A209: Start:23288:0.87: | B209: =FIND(":",$A209,1) -> 6 | C209: =FIND(":",$A209,B209+1) -> 12 | D209: =FIND(":",$A209,C209+1) -> 17 | E209: =FIND(":",$A209,D209+1) -> #VALUE! | F209: ='Data In'!#REF! -> #REF! | G209: ='Data In'!#REF! -> #REF! | H209: =_xlfn.NUMBERVALUE(MID($A209,E209+1,1000)) -> #VALUE! | I209: =AND(G208<Threshold,G209>Threshold) -> #REF! | J209: =IF(Table15[[#This Row],[Rising Through Threshold]],Table15[[#This Row],[Start time]],J208) -> #REF! | K209: =IF(AND(Table15[[#This Row],[Rising Through Threshold]],J208>0),J209-J208,"") -> #REF!
...

Sheet Sheet1
A1: Serial Data | B1: colon 1 | C1: colon 2 | D1: colon 3 | E1: colon 4 | F1: Start time | G1: Voltage | H1: End time | I1: Rising Through Threshold | J1: Last | K1: Period
A2: Start:0.0:0.49:a:a: | B2: =FIND(":",$A2,1) -> 6 | C2: =FIND(":",$A2,B2+1) -> 10 | D2: =FIND(":",$A2,C2+1) -> 15 | E2: =FIND(":",$A2,D2+1) -> 17 | F2: =_xlfn.NUMBERVALUE(MID($A2,B2+1,C2-B2-1)) -> 0 | G2: =_xlfn.NUMBERVALUE(MID($A2,C2+1,D2-C2-1)) -> 0.49 | H2: =_xlfn.NUMBERVALUE(MID($A2,E2+1,1000)) -> #VALUE! | I2: =AND(G1<Threshold,G2>Threshold) -> FALSE | K2: =IF(AND(Table1[[#This Row],[Rising Through Threshold]],J1>0),J2-J1,"")
A3: Start:4.250:1.24:a:a: | B3: =FIND(":",$A3,1) -> 6 | C3: =FIND(":",$A3,B3+1) -> 12 | D3: =FIND(":",$A3,C3+1) -> 17 | E3: =FIND(":",$A3,D3+1) -> 19 | F3: =_xlfn.NUMBERVALUE(MID($A3,B3+1,C3-B3-1)) -> 4.25 | G3: =_xlfn.NUMBERVALUE(MID($A3,C3+1,D3-C3-1)) -> 1.24 | H3: =_xlfn.NUMBERVALUE(MID($A3,E3+1,1000)) -> #VALUE! | I3: =AND(G2<Threshold,G3>Threshold) -> FALSE | J3: =IF(Table1[[#This Row],[Rising Through Threshold]],Table1[[#This Row],[Start time]],J2) -> 0 | K3: =IF(AND(Table1[[#This Row],[Rising Through Threshold]],J2>0),J3-J2,"")
A4: Start:8.500:2.78:a:a: | B4: =FIND(":",$A4,1) -> 6 | C4: =FIND(":",$A4,B4+1) -> 12 | D4: =FIND(":",$A4,C4+1) -> 17 | E4: =FIND(":",$A4,D4+1) -> 19 | F4: =_xlfn.NUMBERVALUE(MID($A4,B4+1,C4-B4-1)) -> 8.5 | G4: =_xlfn.NUMBERVALUE(MID($A4,C4+1,D4-C4-1)) -> 2.78 | H4: =_xlfn.NUMBERVALUE(MID($A4,E4+1,1000)) -> #VALUE! | I4: =AND(G3<Threshold,G4>Threshold) -> TRUE | J4: =IF(Table1[[#This Row],[Rising Through Threshold]],Table1[[#This Row],[Start time]],J3) -> 8.5 | K4: =IF(AND(Table1[[#This Row],[Rising Through Threshold]],J3>0),J4-J3,"")
A5: Start:12.750:3.31:a:a: | B5: =FIND(":",$A5,1) -> 6 | C5: =FIND(":",$A5,B5+1) -> 13 | D5: =FIND(":",$A5,C5+1) -> 18 | E5: =FIND(":",$A5,D5+1) -> 20 | F5: =_xlfn.NUMBERVALUE(MID($A5,B5+1,C5-B5-1)) -> 12.75 | G5: =_xlfn.NUMBERVALUE(MID($A5,C5+1,D5-C5-1)) -> 3.31 | H5: =_xlfn.NUMBERVALUE(MID($A5,E5+1,1000)) -> #VALUE! | I5: =AND(G4<Threshold,G5>Threshold) -> FALSE | J5: =IF(Table1[[#This Row],[Rising Through Threshold]],Table1[[#This Row],[Start time]],J4) -> 8.5 | K5: =IF(AND(Table1[[#This Row],[Rising Through Threshold]],J4>0),J5-J4,"")
A6: Start:17.0:3.82:a:a: | B6: =FIND(":",$A6,1) -> 6 | C6: =FIND(":",$A6,B6+1) -> 11 | D6: =FIND(":",$A6,C6+1) -> 16 | E6: =FIND(":",$A6,D6+1) -> 18 | F6: =_xlfn.NUMBERVALUE(MID($A6,B6+1,C6-B6-1)) -> 17 | G6: =_xlfn.NUMBERVALUE(MID($A6,C6+1,D6-C6-1)) -> 3.82 | H6: =_xlfn.NUMBERVALUE(MID($A6,E6+1,1000)) -> #VALUE! | I6: =AND(G5<Threshold,G6>Threshold) -> FALSE | J6: =IF(Table1[[#This Row],[Rising Through Threshold]],Table1[[#This Row],[Start time]],J5) -> 8.5 | K6: =IF(AND(Table1[[#This Row],[Rising Through Threshold]],J5>0),J6-J5,"")
A7: Start:21.250:5.00:a:a: | B7: =FIND(":",$A7,1) -> 6 | C7: =FIND(":",$A7,B7+1) -> 13 | D7: =FIND(":",$A7,C7+1) -> 18 | E7: =FIND(":",$A7,D7+1) -> 20 | F7: =_xlfn.NUMBERVALUE(MID($A7,B7+1,C7-B7-1)) -> 21.25 | G7: =_xlfn.NUMBERVALUE(MID($A7,C7+1,D7-C7-1)) -> 5 | H7: =_xlfn.NUMBERVALUE(MID($A7,E7+1,1000)) -> #VALUE! | I7: =AND(G6<Threshold,G7>Threshold) -> FALSE | J7: =IF(Table1[[#This Row],[Rising Through Threshold]],Table1[[#This Row],[Start time]],J6) -> 8.5 | K7: =IF(AND(Table1[[#This Row],[Rising Through Threshold]],J6>0),J7-J6,"")
A8: Start:25.500:4.76:a:a: | B8: =FIND(":",$A8,1) -> 6 | C8: =FIND(":",$A8,B8+1) -> 13 | D8: =FIND(":",$A8,C8+1) -> 18 | E8: =FIND(":",$A8,D8+1) -> 20 | F8: =_xlfn.NUMBERVALUE(MID($A8,B8+1,C8-B8-1)) -> 25.5 | G8: =_xlfn.NUMBERVALUE(MID($A8,C8+1,D8-C8-1)) -> 4.76 | H8: =_xlfn.NUMBERVALUE(MID($A8,E8+1,1000)) -> #VALUE! | I8: =AND(G7<Threshold,G8>Threshold) -> FALSE | J8: =IF(Table1[[#This Row],[Rising Through Threshold]],Table1[[#This Row],[Start time]],J7) -> 8.5 | K8: =IF(AND(Table1[[#This Row],[Rising Through Threshold]],J7>0),J8-J7,"")
A9: Start:29.750:3.82:a:a: | B9: =FIND(":",$A9,1) -> 6 | C9: =FIND(":",$A9,B9+1) -> 13 | D9: =FIND(":",$A9,C9+1) -> 18 | E9: =FIND(":",$A9,D9+1) -> 20 | F9: =_xlfn.NUMBERVALUE(MID($A9,B9+1,C9-B9-1)) -> 29.75 | G9: =_xlfn.NUMBERVALUE(MID($A9,C9+1,D9-C9-1)) -> 3.82 | H9: =_xlfn.NUMBERVALUE(MID($A9,E9+1,1000)) -> #VALUE! | I9: =AND(G8<Threshold,G9>Threshold) -> FALSE | J9: =IF(Table1[[#This Row],[Rising Through Threshold]],Table1[[#This Row],[Start time]],J8) -> 8.5 | K9: =IF(AND(Table1[[#This Row],[Rising Through Threshold]],J8>0),J9-J8,"")
A10: Start:34.0:2.88:a:a: | B10: =FIND(":",$A10,1) -> 6 | C10: =FIND(":",$A10,B10+1) -> 11 | D10: =FIND(":",$A10,C10+1) -> 16 | E10: =FIND(":",$A10,D10+1) -> 18 | F10: =_xlfn.NUMBERVALUE(MID($A10,B10+1,C10-B10-1)) -> 34 | G10: =_xlfn.NUMBERVALUE(MID($A10,C10+1,D10-C10-1)) -> 2.88 | H10: =_xlfn.NUMBERVALUE(MID($A10,E10+1,1000)) -> #VALUE! | I10: =AND(G9<Threshold,G10>Threshold) -> FALSE | J10: =IF(Table1[[#This Row],[Rising Through Threshold]],Table1[[#This Row],[Start time]],J9) -> 8.5 | K10: =IF(AND(Table1[[#This Row],[Rising Through Threshold]],J9>0),J10-J9,"")
A11: Start:38.250:1.00:a:a: | B11: =FIND(":",$A11,1) -> 6 | C11: =FIND(":",$A11,B11+1) -> 13 | D11: =FIND(":",$A11,C11+1) -> 18 | E11: =FIND(":",$A11,D11+1) -> 20 | F11: =_xlfn.NUMBERVALUE(MID($A11,B11+1,C11-B11-1)) -> 38.25 | G11: =_xlfn.NUMBERVALUE(MID($A11,C11+1,D11-C11-1)) -> 1 | H11: =_xlfn.NUMBERVALUE(MID($A11,E11+1,1000)) -> #VALUE! | I11: =AND(G10<Threshold,G11>Threshold) -> FALSE | J11: =IF(Table1[[#This Row],[Rising Through Threshold]],Table1[[#This Row],[Start time]],J10) -> 8.5 | K11: =IF(AND(Table1[[#This Row],[Rising Through Threshold]],J10>0),J11-J10,"")
A12: Start:42.500:0.14:a:a: | B12: =FIND(":",$A12,1) -> 6 | C12: =FIND(":",$A12,B12+1) -> 13 | D12: =FIND(":",$A12,C12+1) -> 18 | E12: =FIND(":",$A12,D12+1) -> 20 | F12: =_xlfn.NUMBERVALUE(MID($A12,B12+1,C12-B12-1)) -> 42.5 | G12: =_xlfn.NUMBERVALUE(MID($A12,C12+1,D12-C12-1)) -> 0.14 | H12: =_xlfn.NUMBERVALUE(MID($A12,E12+1,1000)) -> #VALUE! | I12: =AND(G11<Threshold,G12>Threshold) -> FALSE | J12: =IF(Table1[[#This Row],[Rising Through Threshold]],Table1[[#This Row],[Start time]],J11) -> 8.5 | K12: =IF(AND(Table1[[#This Row],[Rising Through Threshold]],J11>0),J12-J11,"")
A13: Start:46.750:0.00:a:a: | B13: =FIND(":",$A13,1) -> 6 | C13: =FIND(":",$A13,B13+1) -> 13 | D13: =FIND(":",$A13,C13+1) -> 18 | E13: =FIND(":",$A13,D13+1) -> 20 | F13: =_xlfn.NUMBERVALUE(MID($A13,B13+1,C13-B13-1)) -> 46.75 | G13: =_xlfn.NUMBERVALUE(MID($A13,C13+1,D13-C13-1)) -> 0 | H13: =_xlfn.NUMBERVALUE(MID($A13,E13+1,1000)) -> #VALUE! | I13: =AND(G12<Threshold,G13>Threshold) -> FALSE | J13: =IF(Table1[[#This Row],[Rising Through Threshold]],Table1[[#This Row],[Start time]],J12) -> 8.5 | K13: =IF(AND(Table1[[#This Row],[Rising Through Threshold]],J12>0),J13-J12,"")
A14: Start:51.0:0.55:a:a: | B14: =FIND(":",$A14,1) -> 6 | C14: =FIND(":",$A14,B14+1) -> 11 | D14: =FIND(":",$A14,C14+1) -> 16 | E14: =FIND(":",$A14,D14+1) -> 18 | F14: =_xlfn.NUMBERVALUE(MID($A14,B14+1,C14-B14-1)) -> 51 | G14: =_xlfn.NUMBERVALUE(MID($A14,C14+1,D14-C14-1)) -> 0.55 | H14: =_xlfn.NUMBERVALUE(MID($A14,E14+1,1000)) -> #VALUE! | I14: =AND(G13<Threshold,G14>Threshold) -> FALSE | J14: =IF(Table1[[#This Row],[Rising Through Threshold]],Table1[[#This Row],[Start time]],J13) -> 8.5 | K14: =IF(AND(Table1[[#This Row],[Rising Through Threshold]],J13>0),J14-J13,"")
... A23: Start:89.250:2.02:a:a: | B23: =FIND(":",$A23,1) -> 6 | C23: =FIND(":",$A23,B23+1) -> 13 | D23: =FIND(":",$A23,C23+1) -> 18 | E23: =FIND(":",$A23,D23+1) -> 20 | F23: =_xlfn.NUMBERVALUE(MID($A23,B23+1,C23-B23-1)) -> 89.25 | G23: =_xlfn.NUMBERVALUE(MID($A23,C23+1,D23-C23-1)) -> 2.02 | H23: =_xlfn.NUMBERVALUE(MID($A23,E23+1,1000)) -> #VALUE! | I23: =AND(G22<Threshold,G23>Threshold) -> FALSE | J23: =IF(Table1[[#This Row],[Rising Through Threshold]],Table1[[#This Row],[Start time]],J22) -> 63.75 | K23: =IF(AND(Table1[[#This Row],[Rising Through Threshold]],J22>0),J23-J22,"")
A24: Start:93.500:0.18:a:a: | B24: =FIND(":",$A24,1) -> 6 | C24: =FIND(":",$A24,B24+1) -> 13 | D24: =FIND(":",$A24,C24+1) -> 18 | E24: =FIND(":",$A24,D24+1) -> 20 | F24: =_xlfn.NUMBERVALUE(MID($A24,B24+1,C24-B24-1)) -> 93.5 | G24: =_xlfn.NUMBERVALUE(MID($A24,C24+1,D24-C24-1)) -> 0.18 | H24: =_xlfn.NUMBERVALUE(MID($A24,E24+1,1000)) -> #VALUE! | I24: =AND(G23<Threshold,G24>Threshold) -> FALSE | J24: =IF(Table1[[#This Row],[Rising Through Threshold]],Table1[[#This Row],[Start time]],J23) -> 63.75 | K24: =IF(AND(Table1[[#This Row],[Rising Through Threshold]],J23>0),J24-J23,"") | N24: Max | O24: =MAX(Table1[Voltage]) -> 5 | R24: Threshold | S24: =O27 -> 2.372125
A25: Start:97.750:0.00:a:a: | B25: =FIND(":",$A25,1) -> 6 | C25: =FIND(":",$A25,B25+1) -> 13 | D25: =FIND(":",$A25,C25+1) -> 18 | E25: =FIND(":",$A25,D25+1) -> 20 | F25: =_xlfn.NUMBERVALUE(MID($A25,B25+1,C25-B25-1)) -> 97.75 | G25: =_xlfn.NUMBERVALUE(MID($A25,C25+1,D25-C25-1)) -> 0 | H25: =_xlfn.NUMBERVALUE(MID($A25,E25+1,1000)) -> #VALUE! | I25: =AND(G24<Threshold,G25>Threshold) -> FALSE | J25: =IF(Table1[[#This Row],[Rising Through Threshold]],Table1[[#This Row],[Start time]],J24) -> 63.75 | K25: =IF(AND(Table1[[#This Row],[Rising Through Threshold]],J24>0),J25-J24,"") | N25: Min | O25: =MIN(Table1[Voltage]) -> 0 | R25: Period | S25: =Table1[[#Totals],[Period]] -> 52.59375
A26: Start:102.0:0.00:a:a: | B26: =FIND(":",$A26,1) -> 6 | C26: =FIND(":",$A26,B26+1) -> 12 | D26: =FIND(":",$A26,C26+1) -> 17 | E26: =FIND(":",$A26,D26+1) -> 19 | F26: =_xlfn.NUMBERVALUE(MID($A26,B26+1,C26-B26-1)) -> 102 | G26: =_xlfn.NUMBERVALUE(MID($A26,C26+1,D26-C26-1)) -> 0 | H26: =_xlfn.NUMBERVALUE(MID($A26,E26+1,1000)) -> #VALUE! | I26: =AND(G25<Threshold,G26>Threshold) -> FALSE | J26: =IF(Table1[[#This Row],[Rising Through Threshold]],Table1[[#This Row],[Start time]],J25) -> 63.75 | K26: =IF(AND(Table1[[#This Row],[Rising Through Threshold]],J25>0),J26-J25,"") | N26: Peak to peak | O26: =O24-O25 -> 5 | R26: Frequency | S26: =1/(S25/1000000) -> 19013.666
A27: Start:106.250:0.49:a:a: | B27: =FIND(":",$A27,1) -> 6 | C27: =FIND(":",$A27,B27+1) -> 14 | D27: =FIND(":",$A27,C27+1) -> 19 | E27: =FIND(":",$A27,D27+1) -> 21 | F27: =_xlfn.NUMBERVALUE(MID($A27,B27+1,C27-B27-1)) -> 106.25 | G27: =_xlfn.NUMBERVALUE(MID($A27,C27+1,D27-C27-1)) -> 0.49 | H27: =_xlfn.NUMBERVALUE(MID($A27,E27+1,1000)) -> #VALUE! | I27: =AND(G26<Threshold,G27>Threshold) -> FALSE | J27: =IF(Table1[[#This Row],[Rising Through Threshold]],Table1[[#This Row],[Start time]],J26) -> 63.75 | K27: =IF(AND(Table1[[#This Row],[Rising Through Threshold]],J26>0),J27-J26,"") | N27: Average | O27: =Table1[[#Totals],[Voltage]] -> 2.372125
A28: Start:110.500:1.94:a:a: | B28: =FIND(":",$A28,1) -> 6 | C28: =FIND(":",$A28,B28+1) -> 14 | D28: =FIND(":",$A28,C28+1) -> 19 | E28: =FIND(":",$A28,D28+1) -> 21 | F28: =_xlfn.NUMBERVALUE(MID($A28,B28+1,C28-B28-1)) -> 110.5 | G28: =_xlfn.NUMBERVALUE(MID($A28,C28+1,D28-C28-1)) -> 1.94 | H28: =_xlfn.NUMBERVALUE(MID($A28,E28+1,1000)) -> #VALUE! | I28: =AND(G27<Threshold,G28>Threshold) -> FALSE | J28: =IF(Table1[[#This Row],[Rising Through Threshold]],Table1[[#This Row],[Start time]],J27) -> 63.75 | K28: =IF(AND(Table1[[#This Row],[Rising Through Threshold]],J27>0),J28-J27,"")
A29: Start:114.750:2.67:a:a: | B29: =FIND(":",$A29,1) -> 6 | C29: =FIND(":",$A29,B29+1) -> 14 | D29: =FIND(":",$A29,C29+1) -> 19 | E29: =FIND(":",$A29,D29+1) -> 21 | F29: =_xlfn.NUMBERVALUE(MID($A29,B29+1,C29-B29-1)) -> 114.75 | G29: =_xlfn.NUMBERVALUE(MID($A29,C29+1,D29-C29-1)) -> 2.67 | H29: =_xlfn.NUMBERVALUE(MID($A29,E29+1,1000)) -> #VALUE! | I29: =AND(G28<Threshold,G29>Threshold) -> TRUE | J29: =IF(Table1[[#This Row],[Rising Through Threshold]],Table1[[#This Row],[Start time]],J28) -> 114.75 | K29: =IF(AND(Table1[[#This Row],[Rising Through Threshold]],J28>0),J29-J28,"") -> 51
A30: Start:119.0:3.27:a:a: | B30: =FIND(":",$A30,1) -> 6 | C30: =FIND(":",$A30,B30+1) -> 12 | D30: =FIND(":",$A30,C30+1) -> 17 | E30: =FIND(":",$A30,D30+1) -> 19 | F30: =_xlfn.NUMBERVALUE(MID($A30,B30+1,C30-B30-1)) -> 119 | G30: =_xlfn.NUMBERVALUE(MID($A30,C30+1,D30-C30-1)) -> 3.27 | H30: =_xlfn.NUMBERVALUE(MID($A30,E30+1,1000)) -> #VALUE! | I30: =AND(G29<Threshold,G30>Threshold) -> FALSE | J30: =IF(Table1[[#This Row],[Rising Through Threshold]],Table1[[#This Row],[Start time]],J29) -> 114.75 | K30: =IF(AND(Table1[[#This Row],[Rising Through Threshold]],J29>0),J30-J29,"")
A31: Start:123.250:4.71:a:a: | B31: =FIND(":",$A31,1) -> 6 | C31: =FIND(":",$A31,B31+1) -> 14 | D31: =FIND(":",$A31,C31+1) -> 19 | E31: =FIND(":",$A31,D31+1) -> 21 | F31: =_xlfn.NUMBERVALUE(MID($A31,B31+1,C31-B31-1)) -> 123.25 | G31: =_xlfn.NUMBERVALUE(MID($A31,C31+1,D31-C31-1)) -> 4.71 | H31: =_xlfn.NUMBERVALUE(MID($A31,E31+1,1000)) -> #VALUE! | I31: =AND(G30<Threshold,G31>Threshold) -> FALSE | J31: =IF(Table1[[#This Row],[Rising Through Threshold]],Table1[[#This Row],[Start time]],J30) -> 114.75 | K31: =IF(AND(Table1[[#This Row],[Rising Through Threshold]],J30>0),J31-J30,"")
A32: Start:127.500:5.00:a:a: | B32: =FIND(":",$A32,1) -> 6 | C32: =FIND(":",$A32,B32+1) -> 14 | D32: =FIND(":",$A32,C32+1) -> 19 | E32: =FIND(":",$A32,D32+1) -> 21 | F32: =_xlfn.NUMBERVALUE(MID($A32,B32+1,C32-B32-1)) -> 127.5 | G32: =_xlfn.NUMBERVALUE(MID($A32,C32+1,D32-C32-1)) -> 5 | H32: =_xlfn.NUMBERVALUE(MID($A32,E32+1,1000)) -> #VALUE! | I32: =AND(G31<Threshold,G32>Threshold) -> FALSE | J32: =IF(Table1[[#This Row],[Rising Through Threshold]],Table1[[#This Row],[Start time]],J31) -> 114.75 | K32: =IF(AND(Table1[[#This Row],[Rising Through Threshold]],J31>0),J32-J31,"")
A33: Start:131.750:4.86:a:a: | B33: =FIND(":",$A33,1) -> 6 | C33: =FIND(":",$A33,B33+1) -> 14 | D33: =FIND(":",$A33,C33+1) -> 19 | E33: =FIND(":",$A33,D33+1) -> 21 | F33: =_xlfn.NUMBERVALUE(MID($A33,B33+1,C33-B33-1)) -> 131.75 | G33: =_xlfn.NUMBERVALUE(MID($A33,C33+1,D33-C33-1)) -> 4.86 | H33: =_xlfn.NUMBERVALUE(MID($A33,E33+1,1000)) -> #VALUE! | I33: =AND(G32<Threshold,G33>Threshold) -> FALSE | J33: =IF(Table1[[#This Row],[Rising Through Threshold]],Table1[[#This Row],[Start time]],J32) -> 114.75 | K33: =IF(AND(Table1[[#This Row],[Rising Through Threshold]],J32>0),J33-J32,"")
A34: Start:136.0:3.00:a:a: | B34: =FIND(":",$A34,1) -> 6 | C34: =FIND(":",$A34,B34+1) -> 12 | D34: =FIND(":",$A34,C34+1) -> 17 | E34: =FIND(":",$A34,D34+1) -> 19 | F34: =_xlfn.NUMBERVALUE(MID($A34,B34+1,C34-B34-1)) -> 136 | G34: =_xlfn.NUMBERVALUE(MID($A34,C34+1,D34-C34-1)) -> 3 | H34: =_xlfn.NUMBERVALUE(MID($A34,E34+1,1000)) -> #VALUE! | I34: =AND(G33<Threshold,G34>Threshold) -> FALSE | J34: =IF(Table1[[#This Row],[Rising Through Threshold]],Table1[[#This Row],[Start time]],J33) -> 114.75 | K34: =IF(AND(Table1[[#This Row],[Rising Through Threshold]],J33>0),J34-J33,"")
A35: Start:140.250:2.06:a:a: | B35: =FIND(":",$A35,1) -> 6 | C35: =FIND(":",$A35,B35+1) -> 14 | D35: =FIND(":",$A35,C35+1) -> 19 | E35: =FIND(":",$A35,D35+1) -> 21 | F35: =_xlfn.NUMBERVALUE(MID($A35,B35+1,C35-B35-1)) -> 140.25 | G35: =_xlfn.NUMBERVALUE(MID($A35,C35+1,D35-C35-1)) -> 2.06 | H35: =_xlfn.NUMBERVALUE(MID($A35,E35+1,1000)) -> #VALUE! | I35: =AND(G34<Threshold,G35>Threshold) -> FALSE | J35: =IF(Table1[[#This Row],[Rising Through Threshold]],Table1[[#This Row],[Start time]],J34) -> 114.75 | K35: =IF(AND(Table1[[#This Row],[Rising Through Threshold]],J34>0),J35-J34,"")
A36: Start:144.500:1.10:a:a: | B36: =FIND(":",$A36,1) -> 6 | C36: =FIND(":",$A36,B36+1) -> 14 | D36: =FIND(":",$A36,C36+1) -> 19 | E36: =FIND(":",$A36,D36+1) -> 21 | F36: =_xlfn.NUMBERVALUE(MID($A36,B36+1,C36-B36-1)) -> 144.5 | G36: =_xlfn.NUMBERVALUE(MID($A36,C36+1,D36-C36-1)) -> 1.1 | H36: =_xlfn.NUMBERVALUE(MID($A36,E36+1,1000)) -> #VALUE! | I36: =AND(G35<Threshold,G36>Threshold) -> FALSE | J36: =IF(Table1[[#This Row],[Rising Through Threshold]],Table1[[#This Row],[Start time]],J35) -> 114.75 | K36: =IF(AND(Table1[[#This Row],[Rising Through Threshold]],J35>0),J36-J35,"")
A37: Start:148.750:0.18:a:a: | B37: =FIND(":",$A37,1) -> 6 | C37: =FIND(":",$A37,B37+1) -> 14 | D37: =FIND(":",$A37,C37+1) -> 19 | E37: =FIND(":",$A37,D37+1) -> 21 | F37: =_xlfn.NUMBERVALUE(MID($A37,B37+1,C37-B37-1)) -> 148.75 | G37: =_xlfn.NUMBERVALUE(MID($A37,C37+1,D37-C37-1)) -> 0.18 | H37: =_xlfn.NUMBERVALUE(MID($A37,E37+1,1000)) -> #VALUE! | I37: =AND(G36<Threshold,G37>Threshold) -> FALSE | J37: =IF(Table1[[#This Row],[Rising Through Threshold]],Table1[[#This Row],[Start time]],J36) -> 114.75 | K37: =IF(AND(Table1[[#This Row],[Rising Through Threshold]],J36>0),J37-J36,"")
A38: Start:153.0:0.00:a:a: | B38: =FIND(":",$A38,1) -> 6 | C38: =FIND(":",$A38,B38+1) -> 12 | D38: =FIND(":",$A38,C38+1) -> 17 | E38: =FIND(":",$A38,D38+1) -> 19 | F38: =_xlfn.NUMBERVALUE(MID($A38,B38+1,C38-B38-1)) -> 153 | G38: =_xlfn.NUMBERVALUE(MID($A38,C38+1,D38-C38-1)) -> 0 | H38: =_xlfn.NUMBERVALUE(MID($A38,E38+1,1000)) -> #VALUE! | I38: =AND(G37<Threshold,G38>Threshold) -> FALSE | J38: =IF(Table1[[#This Row],[Rising Through Threshold]],Table1[[#This Row],[Start time]],J37) -> 114.75 | K38: =IF(AND(Table1[[#This Row],[Rising Through Threshold]],J37>0),J38-J37,"")
A39: Start:157.250:0.47:a:a: | B39: =FIND(":",$A39,1) -> 6 | C39: =FIND(":",$A39,B39+1) -> 14 | D39: =FIND(":",$A39,C39+1) -> 19 | E39: =FIND(":",$A39,D39+1) -> 21 | F39: =_xlfn.NUMBERVALUE(MID($A39,B39+1,C39-B39-1)) -> 157.25 | G39: =_xlfn.NUMBERVALUE(MID($A39,C39+1,D39-C39-1)) -> 0.47 | H39: =_xlfn.NUMBERVALUE(MID($A39,E39+1,1000)) -> #VALUE! | I39: =AND(G38<Threshold,G39>Threshold) -> FALSE | J39: =IF(Table1[[#This Row],[Rising Through Threshold]],Table1[[#This Row],[Start time]],J38) -> 114.75 | K39: =IF(AND(Table1[[#This Row],[Rising Through Threshold]],J38>0),J39-J38,"")
... A401: Start:1695.750:4.00:a:a: | B401: =FIND(":",$A401,1) -> 6 | C401: =FIND(":",$A401,B401+1) -> 15 | D401: =FIND(":",$A401,C401+1) -> 20 | E401: =FIND(":",$A401,D401+1) -> 22 | F401: =_xlfn.NUMBERVALUE(MID($A401,B401+1,C401-B401-1)) -> 1695.75 | G401: =_xlfn.NUMBERVALUE(MID($A401,C401+1,D401-C401-1)) -> 4 | H401: =_xlfn.NUMBERVALUE(MID($A401,E401+1,1000)) -> #VALUE! | I401: =AND(G400<Threshold,G401>Threshold) -> FALSE | J401: =IF(Table1[[#This Row],[Rising Through Threshold]],Table1[[#This Row],[Start time]],J400) -> 1691.5 | K401: =IF(AND(Table1[[#This Row],[Rising Through Threshold]],J400>0),J401-J400,"")
A402: Total | G402: =SUBTOTAL(101,Table1[Voltage]) -> 2.372125 | K402: =SUBTOTAL(101,Table1[Period]) -> 52.59375

Sheet Data In
A1: Data In (From Arduino Uno (COM3))
A2: Data coming from the current data source will appear below as it is received.
A3: Current Data
A4: TIME | B4: CH1 | C4: CH2 | D4: CH3 | E4: CH4 | F4: CH5 | G4: CH6 | H4: CH7 | I4: CH8 | J4: CH9 | K4: CH10
A5: 45997.682 | B5: 5205.84 | C5: 2.84 | D5: a | E5: a | F5: 4000 | G5: 5 | H5: 0 | I5: 7
A6: Historical Data
A7: TIME | B7: CH1 | C7: CH2 | D7: CH3 | E7: CH4 | F7: CH5 | G7: CH6 | H7: CH7 | I7: CH8 | J7: CH9 | K7: CH10
A8: 45997.682 | B8: 0 | C8: 0.51 | D8: a | E8: a | F8: 4000 | G8: 5 | H8: 1 | I8: 0
A9: 45997.682 | B9: 26.16 | C9: 0.63 | D9: a | E9: a | F9: 4000 | G9: 5 | H9: 1 | I9: 0
A10: 45997.682 | B10: 52.32 | C10: 0.8 | D10: a | E10: a | F10: 4000 | G10: 5 | H10: 1 | I10: 0
A11: 45997.682 | B11: 78.48 | C11: 1.06 | D11: a | E11: a | F11: 4000 | G11: 5 | H11: 1 | I11: 0
A12: 45997.682 | B12: 104.64 | C12: 1.31 | D12: a | E12: a | F12: 4000 | G12: 5 | H12: 1 | I12: 0
A13: 45997.682 | B13: 130.8 | C13: 1.59 | D13: a | E13: a | F13: 4000 | G13: 5 | H13: 1 | I13: 0
A14: 45997.682 | B14: 156.96 | C14: 1.84 | D14: a | E14: a | F14: 4000 | G14: 5 | H14: 1 | I14: 0
A15: 45997.682 | B15: 183.12 | C15: 2.1 | D15: a | E15: a | F15: 4000 | G15: 5 | H15: 0 | I15: 1
A16: 45997.682 | B16: 209.28 | C16: 2.31 | D16: a | E16: a | F16: 4000 | G16: 5 | H16: 0 | I16: 1
A17: 45997.682 | B17: 235.44 | C17: 2.53 | D17: a | E17: a | F17: 4000 | G17: 5 | H17: 0 | I17: 1
A18: 45997.682 | B18: 261.6 | C18: 2.71 | D18: a | E18: a | F18: 4000 | G18: 5 | H18: 0 | I18: 1
A19: 45997.682 | B19: 287.76 | C19: 2.88 | D19: a | E19: a | F19: 4000 | G19: 5 | H19: 0 | I19: 1
... A207: 45997.682 | B207: 5205.84 | C207: 2.84 | D207: a | E207: a | F207: 4000 | G207: 5 | H207: 0 | I207: 7

Sheet Data Out
A1: Data Out (To Device)
A2: Data entered into the channels below will be sent to the currently connected device as a comma-delimited string.
A4: CH1 | B4: CH2 | C4: CH3 | D4: CH4 | E4: CH5 | F4: CH6 | G4: CH7 | H4: CH8 | I4: CH9 | J4: CH10
A5: ='CH2 DStream'!AB33 -> 4000 | B5: ='CH2 DStream'!AB34 -> 5

Sheet Settings
A1: Workbook Settings
A2: Settings below will affect how data is read into the current workbook from data sources. Clear a field's contents to revert to its default setting.
A4: Data interval (ms) | B4: 150 | C4: 150
A6: Data rows | B6: 15 | C6: 200
A8: Data channels | B8: 10 | C8: 10
A10: Data orientation | B10: Newest last | C10: Newest last
A13: WARNING: Changing settings may result in the loss of content and/or custom formatting in the Data In and Data Out worksheets. Always save before changing values.

Sheet Manifest
A1: Arduino Uno | L1: {"Channels":[{"Description":null,"Id":null,"IsGhost":false,"Name":null,"Status":"Active","SubChannels":[{"Description":null,"Id":"CH1","IsGhost":false,"Name":"CH1","Status":"Active","SubChannels":[],"UnitOfMeasure":null},{"Description":null,"Id":"CH2","IsGhost":false,"Name":"CH2","Status":"Active","SubChannels":[],"UnitOfMeasure":null},{"Description":null,"Id":"CH3","IsGhost":false,"Name":"CH3","Status":"Active","SubChannels":[],"UnitOfMeasure":null},{"Description":null,"Id":"CH4","IsGhost":false,"Name":"CH4","Status":"Active","SubChannels":[],"UnitOfMeasure":null},{"Description":null,"Id":"CH5","IsGhost":false,"Name":"CH5","Status":"Active","SubChannels":[],"UnitOfMeasure":null},{"Description":null,"Id":"CH6","IsGhost":false,"Name":"CH6","Status":"Active","SubChannels":[],"UnitOfMeasure":null},{"Description":null,"Id":"CH7","IsGhost":false,"Name":"CH7","Status":"Active","SubChannels":[],"UnitOfMeasure":null},{"Description":null,"Id":"CH8","IsGhost":false,"Name":"CH8","Status":"Active","SubChannels":[],"UnitOfMeasure":null},{"Description":null,"Id":"CH9","IsGhost":false,"Name":"CH9","Status":"Active","SubChannels":[],"UnitOfMeasure":null},{"Description":null,"Id":"CH10","IsGhost":false,"Name":"CH10","Status":"Active","SubChannels":[],"UnitOfMeasure":null}],"UnitOfMeasure":null}],"Commands":[],"DataInterval":150,"Id":"EA312006-51C5-4E13-A001-13DBEA7DC431","IsGenerated":true,"Name":"Arduino Uno","Version":null,"BaudRate":38400}
A2: This manifest was generated for the connected device. You can edit the device name and channel data here and the Data In worksheet will be updated.
B3: Channels
I4: Data Source Id
C5: Id | D5: Name | E5: Description | F5: Unit of Measure | G5: Active | I5: EA312006-51C5-4E13-A001-13DBEA7DC431 | K5: 1
C6: CH1 | D6: CH1 | G6: ü | I6: Data Interval (ms)
C7: CH2 | D7: CH2 | G7: ü | I7: 150
C8: CH3 | D8: CH3 | G8: ü | I8: Baud Rate
C9: CH4 | D9: CH4 | G9: ü | I9: 38400
C10: CH5 | D10: CH5 | G10: ü
C11: CH6 | D11: CH6 | G11: ü
C12: CH7 | D12: CH7 | G12: ü
C13: CH8 | D13: CH8 | G13: ü
C14: CH9 | D14: CH9 | G14: ü
C15: CH10 | D15: CH10 | G15: ü

Sheet CH2 DStream
A1: Serial Data | B1: colon 1 | C1: colon 2 | D1: colon 3 | E1: colon 4 | F1: Start time | G1: Voltage | H1: End time | I1: Rising Through Threshold | J1: Last | K1: Period | L1: Above Theshold | M1: include in duty | N1: Start time2 | O1: Voltage2 | P1: End time2 | Q1: Rising Through Threshold2 | R1: Last2 | S1: Period2 | T1: Above Threshold2 | U1: include in duty2 | V1: not restart | W1: seq | X1: =MAX(X2:X201) -> 0 | Y1: count
A2: Start:8:4.18: | B2: =FIND(":",$A2,1) -> 6 | C2: =FIND(":",$A2,B2+1) -> 8 | D2: =FIND(":",$A2,C2+1) -> 13 | E2: =FIND(":",$A2,D2+1) -> #VALUE! | F2: =IF(Table156[[#This Row],[seq]]>=Table156[[#Totals],[seq]],'Data In'!B8,"") -> 0 | G2: ='Data In'!C8 -> 0.51 | H2: =_xlfn.NUMBERVALUE(MID($A2,E2+1,1000)) -> #VALUE! | I2: =AND(G1<Threshold,G2>Threshold) -> FALSE | K2: =IF(AND(Table156[[#This Row],[Rising Through Threshold]],J1>0),J2-J1,"") | L2: =IF(Table156[[#This Row],[Voltage]]>Threshold,1,0) -> 0 | M2: =AND(Table156[[#This Row],[Last]]>0,Table156[[#This Row],[Last]]<MAX(Table156[Last])) -> FALSE | N2: ='Data In'!D8 -> a | O2: ='Data In'!E8 -> a | P2: =_xlfn.NUMBERVALUE(MID($A2,K2+1,1000)) -> #VALUE! | Q2: =AND(O1<Threshold2,O2>Threshold2) -> #DIV/0! | S2: =IF(AND(Table156[[#This Row],[Rising Through Threshold2]],R1>0),R2-R1,"") -> #DIV/0! | T2: =IF(Table156[[#This Row],[Voltage2]]>Threshold2,1,0) -> #DIV/0! | U2: =AND(Table156[[#This Row],[Last2]]>0,Table156[[#This Row],[Last2]]<MAX(Table156[Last2])) -> #DIV/0! | V2: =OR('Data In'!B8>'Data In'!B7) -> FALSE | W2: =COUNTIF($V$2:V2,"false") -> 1 | Y2: =COUNTIF(Table156[include in duty2],TRUE) -> 0
A3: Start:216:4.09: | B3: =FIND(":",$A3,1) -> 6 | C3: =FIND(":",$A3,B3+1) -> 10 | D3: =FIND(":",$A3,C3+1) -> 15 | E3: =FIND(":",$A3,D3+1) -> #VALUE! | F3: =IF(Table156[[#This Row],[seq]]>=Table156[[#Totals],[seq]],'Data In'!B9,"") -> 26.16 | G3: ='Data In'!C9 -> 0.63 | H3: =_xlfn.NUMBERVALUE(MID($A3,E3+1,1000)) -> #VALUE! | I3: =AND(G2<Threshold,G3>Threshold) -> FALSE | J3: =IF(Table156[[#This Row],[Rising Through Threshold]],Table156[[#This Row],[Start time]],J2) -> 0 | K3: =IF(AND(Table156[[#This Row],[Rising Through Threshold]],J2>0),J3-J2,"") | L3: =IF(Table156[[#This Row],[Voltage]]>Threshold,1,0) -> 0 | M3: =AND(Table156[[#This Row],[Last]]>0,Table156[[#This Row],[Last]]<MAX(Table156[Last])) -> FALSE | N3: ='Data In'!D9 -> a | O3: ='Data In'!E9 -> a | P3: =_xlfn.NUMBERVALUE(MID($A3,K3+1,1000)) -> #VALUE! | Q3: =AND(O2<Threshold2,O3>Threshold2) -> #DIV/0! | R3: =IF(Table156[[#This Row],[Rising Through Threshold2]],Table156[[#This Row],[Start time2]],R2) -> #DIV/0! | S3: =IF(AND(Table156[[#This Row],[Rising Through Threshold2]],R2>0),R3-R2,"") -> #DIV/0! | T3: =IF(Table156[[#This Row],[Voltage2]]>Threshold2,1,0) -> #DIV/0! | U3: =AND(Table156[[#This Row],[Last2]]>0,Table156[[#This Row],[Last2]]<MAX(Table156[Last2])) -> #DIV/0! | V3: =OR('Data In'!B9>'Data In'!B8) -> TRUE | W3: =COUNTIF($V$2:V3,"false") -> 1 | Y3: sum
A4: Start:328:3.92: | B4: =FIND(":",$A4,1) -> 6 | C4: =FIND(":",$A4,B4+1) -> 10 | D4: =FIND(":",$A4,C4+1) -> 15 | E4: =FIND(":",$A4,D4+1) -> #VALUE! | F4: =IF(Table156[[#This Row],[seq]]>=Table156[[#Totals],[seq]],'Data In'!B10,"") -> 52.32 | G4: ='Data In'!C10 -> 0.8 | H4: =_xlfn.NUMBERVALUE(MID($A4,E4+1,1000)) -> #VALUE! | I4: =AND(G3<Threshold,G4>Threshold) -> FALSE | J4: =IF(Table156[[#This Row],[Rising Through Threshold]],Table156[[#This Row],[Start time]],J3) -> 0 | K4: =IF(AND(Table156[[#This Row],[Rising Through Threshold]],J3>0),J4-J3,"") | L4: =IF(Table156[[#This Row],[Voltage]]>Threshold,1,0) -> 0 | M4: =AND(Table156[[#This Row],[Last]]>0,Table156[[#This Row],[Last]]<MAX(Table156[Last])) -> FALSE | N4: ='Data In'!D10 -> a | O4: ='Data In'!E10 -> a | P4: =_xlfn.NUMBERVALUE(MID($A4,K4+1,1000)) -> #VALUE! | Q4: =AND(O3<Threshold2,O4>Threshold2) -> #DIV/0! | R4: =IF(Table156[[#This Row],[Rising Through Threshold2]],Table156[[#This Row],[Start time2]],R3) -> #DIV/0! | S4: =IF(AND(Table156[[#This Row],[Rising Through Threshold2]],R3>0),R4-R3,"") -> #DIV/0! | T4: =IF(Table156[[#This Row],[Voltage2]]>Threshold2,1,0) -> #DIV/0! | U4: =AND(Table156[[#This Row],[Last2]]>0,Table156[[#This Row],[Last2]]<MAX(Table156[Last2])) -> #DIV/0! | V4: =OR('Data In'!B10>'Data In'!B9) -> TRUE | W4: =COUNTIF($V$2:V4,"false") -> 1 | Y4: =SUMIF(Table156[include in duty2],TRUE,Table156[Above Threshold2]) -> 0
A5: Start:440:3.68: | B5: =FIND(":",$A5,1) -> 6 | C5: =FIND(":",$A5,B5+1) -> 10 | D5: =FIND(":",$A5,C5+1) -> 15 | E5: =FIND(":",$A5,D5+1) -> #VALUE! | F5: =IF(Table156[[#This Row],[seq]]>=Table156[[#Totals],[seq]],'Data In'!B11,"") -> 78.48 | G5: ='Data In'!C11 -> 1.06 | H5: =_xlfn.NUMBERVALUE(MID($A5,E5+1,1000)) -> #VALUE! | I5: =AND(G4<Threshold,G5>Threshold) -> FALSE | J5: =IF(Table156[[#This Row],[Rising Through Threshold]],Table156[[#This Row],[Start time]],J4) -> 0 | K5: =IF(AND(Table156[[#This Row],[Rising Through Threshold]],J4>0),J5-J4,"") | L5: =IF(Table156[[#This Row],[Voltage]]>Threshold,1,0) -> 0 | M5: =AND(Table156[[#This Row],[Last]]>0,Table156[[#This Row],[Last]]<MAX(Table156[Last])) -> FALSE | N5: ='Data In'!D11 -> a | O5: ='Data In'!E11 -> a | P5: =_xlfn.NUMBERVALUE(MID($A5,K5+1,1000)) -> #VALUE! | Q5: =AND(O4<Threshold2,O5>Threshold2) -> #DIV/0! | R5: =IF(Table156[[#This Row],[Rising Through Threshold2]],Table156[[#This Row],[Start time2]],R4) -> #DIV/0! | S5: =IF(AND(Table156[[#This Row],[Rising Through Threshold2]],R4>0),R5-R4,"") -> #DIV/0! | T5: =IF(Table156[[#This Row],[Voltage2]]>Threshold2,1,0) -> #DIV/0! | U5: =AND(Table156[[#This Row],[Last2]]>0,Table156[[#This Row],[Last2]]<MAX(Table156[Last2])) -> #DIV/0! | V5: =OR('Data In'!B11>'Data In'!B10) -> TRUE | W5: =COUNTIF($V$2:V5,"false") -> 1 | Y5: count
A6: Start:552:3.39: | B6: =FIND(":",$A6,1) -> 6 | C6: =FIND(":",$A6,B6+1) -> 10 | D6: =FIND(":",$A6,C6+1) -> 15 | E6: =FIND(":",$A6,D6+1) -> #VALUE! | F6: =IF(Table156[[#This Row],[seq]]>=Table156[[#Totals],[seq]],'Data In'!B12,"") -> 104.64 | G6: ='Data In'!C12 -> 1.31 | H6: =_xlfn.NUMBERVALUE(MID($A6,E6+1,1000)) -> #VALUE! | I6: =AND(G5<Threshold,G6>Threshold) -> FALSE | J6: =IF(Table156[[#This Row],[Rising Through Threshold]],Table156[[#This Row],[Start time]],J5) -> 0 | K6: =IF(AND(Table156[[#This Row],[Rising Through Threshold]],J5>0),J6-J5,"") | L6: =IF(Table156[[#This Row],[Voltage]]>Threshold,1,0) -> 0 | M6: =AND(Table156[[#This Row],[Last]]>0,Table156[[#This Row],[Last]]<MAX(Table156[Last])) -> FALSE | N6: ='Data In'!D12 -> a | O6: ='Data In'!E12 -> a | P6: =_xlfn.NUMBERVALUE(MID($A6,K6+1,1000)) -> #VALUE! | Q6: =AND(O5<Threshold2,O6>Threshold2) -> #DIV/0! | R6: =IF(Table156[[#This Row],[Rising Through Threshold2]],Table156[[#This Row],[Start time2]],R5) -> #DIV/0! | S6: =IF(AND(Table156[[#This Row],[Rising Through Threshold2]],R5>0),R6-R5,"") -> #DIV/0! | T6: =IF(Table156[[#This Row],[Voltage2]]>Threshold2,1,0) -> #DIV/0! | U6: =AND(Table156[[#This Row],[Last2]]>0,Table156[[#This Row],[Last2]]<MAX(Table156[Last2])) -> #DIV/0! | V6: =OR('Data In'!B12>'Data In'!B11) -> TRUE | W6: =COUNTIF($V$2:V6,"false") -> 1 | Y6: =COUNTIF(Table156[include in duty],TRUE) -> 175
A7: Start:664:3.06: | B7: =FIND(":",$A7,1) -> 6 | C7: =FIND(":",$A7,B7+1) -> 10 | D7: =FIND(":",$A7,C7+1) -> 15 | E7: =FIND(":",$A7,D7+1) -> #VALUE! | F7: =IF(Table156[[#This Row],[seq]]>=Table156[[#Totals],[seq]],'Data In'!B13,"") -> 130.8 | G7: ='Data In'!C13 -> 1.59 | H7: =_xlfn.NUMBERVALUE(MID($A7,E7+1,1000)) -> #VALUE! | I7: =AND(G6<Threshold,G7>Threshold) -> FALSE | J7: =IF(Table156[[#This Row],[Rising Through Threshold]],Table156[[#This Row],[Start time]],J6) -> 0 | K7: =IF(AND(Table156[[#This Row],[Rising Through Threshold]],J6>0),J7-J6,"") | L7: =IF(Table156[[#This Row],[Voltage]]>Threshold,1,0) -> 0 | M7: =AND(Table156[[#This Row],[Last]]>0,Table156[[#This Row],[Last]]<MAX(Table156[Last])) -> FALSE | N7: ='Data In'!D13 -> a | O7: ='Data In'!E13 -> a | P7: =_xlfn.NUMBERVALUE(MID($A7,K7+1,1000)) -> #VALUE! | Q7: =AND(O6<Threshold2,O7>Threshold2) -> #DIV/0! | R7: =IF(Table156[[#This Row],[Rising Through Threshold2]],Table156[[#This Row],[Start time2]],R6) -> #DIV/0! | S7: =IF(AND(Table156[[#This Row],[Rising Through Threshold2]],R6>0),R7-R6,"") -> #DIV/0! | T7: =IF(Table156[[#This Row],[Voltage2]]>Threshold2,1,0) -> #DIV/0! | U7: =AND(Table156[[#This Row],[Last2]]>0,Table156[[#This Row],[Last2]]<MAX(Table156[Last2])) -> #DIV/0! | V7: =OR('Data In'!B13>'Data In'!B12) -> TRUE | W7: =COUNTIF($V$2:V7,"false") -> 1 | Y7: sum
A8: Start:776:2.71: | B8: =FIND(":",$A8,1) -> 6 | C8: =FIND(":",$A8,B8+1) -> 10 | D8: =FIND(":",$A8,C8+1) -> 15 | E8: =FIND(":",$A8,D8+1) -> #VALUE! | F8: =IF(Table156[[#This Row],[seq]]>=Table156[[#Totals],[seq]],'Data In'!B14,"") -> 156.96 | G8: ='Data In'!C14 -> 1.84 | H8: =_xlfn.NUMBERVALUE(MID($A8,E8+1,1000)) -> #VALUE! | I8: =AND(G7<Threshold,G8>Threshold) -> FALSE | J8: =IF(Table156[[#This Row],[Rising Through Threshold]],Table156[[#This Row],[Start time]],J7) -> 0 | K8: =IF(AND(Table156[[#This Row],[Rising Through Threshold]],J7>0),J8-J7,"") | L8: =IF(Table156[[#This Row],[Voltage]]>Threshold,1,0) -> 0 | M8: =AND(Table156[[#This Row],[Last]]>0,Table156[[#This Row],[Last]]<MAX(Table156[Last])) -> FALSE | N8: ='Data In'!D14 -> a | O8: ='Data In'!E14 -> a | P8: =_xlfn.NUMBERVALUE(MID($A8,K8+1,1000)) -> #VALUE! | Q8: =AND(O7<Threshold2,O8>Threshold2) -> #DIV/0! | R8: =IF(Table156[[#This Row],[Rising Through Threshold2]],Table156[[#This Row],[Start time2]],R7) -> #DIV/0! | S8: =IF(AND(Table156[[#This Row],[Rising Through Threshold2]],R7>0),R8-R7,"") -> #DIV/0! | T8: =IF(Table156[[#This Row],[Voltage2]]>Threshold2,1,0) -> #DIV/0! | U8: =AND(Table156[[#This Row],[Last2]]>0,Table156[[#This Row],[Last2]]<MAX(Table156[Last2])) -> #DIV/0! | V8: =OR('Data In'!B14>'Data In'!B13) -> TRUE | W8: =COUNTIF($V$2:V8,"false") -> 1 | Y8: =SUMIF(Table156[include in duty],TRUE,Table156[Above Theshold]) -> 96
A9: Start:888:2.34: | B9: =FIND(":",$A9,1) -> 6 | C9: =FIND(":",$A9,B9+1) -> 10 | D9: =FIND(":",$A9,C9+1) -> 15 | E9: =FIND(":",$A9,D9+1) -> #VALUE! | F9: =IF(Table156[[#This Row],[seq]]>=Table156[[#Totals],[seq]],'Data In'!B15,"") -> 183.12 | G9: ='Data In'!C15 -> 2.1 | H9: =_xlfn.NUMBERVALUE(MID($A9,E9+1,1000)) -> #VALUE! | I9: =AND(G8<Threshold,G9>Threshold) -> FALSE | J9: =IF(Table156[[#This Row],[Rising Through Threshold]],Table156[[#This Row],[Start time]],J8) -> 0 | K9: =IF(AND(Table156[[#This Row],[Rising Through Threshold]],J8>0),J9-J8,"") | L9: =IF(Table156[[#This Row],[Voltage]]>Threshold,1,0) -> 0 | M9: =AND(Table156[[#This Row],[Last]]>0,Table156[[#This Row],[Last]]<MAX(Table156[Last])) -> FALSE | N9: ='Data In'!D15 -> a | O9: ='Data In'!E15 -> a | P9: =_xlfn.NUMBERVALUE(MID($A9,K9+1,1000)) -> #VALUE! | Q9: =AND(O8<Threshold2,O9>Threshold2) -> #DIV/0! | R9: =IF(Table156[[#This Row],[Rising Through Threshold2]],Table156[[#This Row],[Start time2]],R8) -> #DIV/0! | S9: =IF(AND(Table156[[#This Row],[Rising Through Threshold2]],R8>0),R9-R8,"") -> #DIV/0! | T9: =IF(Table156[[#This Row],[Voltage2]]>Threshold2,1,0) -> #DIV/0! | U9: =AND(Table156[[#This Row],[Last2]]>0,Table156[[#This Row],[Last2]]<MAX(Table156[Last2])) -> #DIV/0! | V9: =OR('Data In'!B15>'Data In'!B14) -> TRUE | W9: =COUNTIF($V$2:V9,"false") -> 1
A10: Start:1000:1.97: | B10: =FIND(":",$A10,1) -> 6 | C10: =FIND(":",$A10,B10+1) -> 11 | D10: =FIND(":",$A10,C10+1) -> 16 | E10: =FIND(":",$A10,D10+1) -> #VALUE! | F10: =IF(Table156[[#This Row],[seq]]>=Table156[[#Totals],[seq]],'Data In'!B16,"") -> 209.28 | G10: ='Data In'!C16 -> 2.31 | H10: =_xlfn.NUMBERVALUE(MID($A10,E10+1,1000)) -> #VALUE! | I10: =AND(G9<Threshold,G10>Threshold) -> FALSE | J10: =IF(Table156[[#This Row],[Rising Through Threshold]],Table156[[#This Row],[Start time]],J9) -> 0 | K10: =IF(AND(Table156[[#This Row],[Rising Through Threshold]],J9>0),J10-J9,"") | L10: =IF(Table156[[#This Row],[Voltage]]>Threshold,1,0) -> 0 | M10: =AND(Table156[[#This Row],[Last]]>0,Table156[[#This Row],[Last]]<MAX(Table156[Last])) -> FALSE | N10: ='Data In'!D16 -> a | O10: ='Data In'!E16 -> a | P10: =_xlfn.NUMBERVALUE(MID($A10,K10+1,1000)) -> #VALUE! | Q10: =AND(O9<Threshold2,O10>Threshold2) -> #DIV/0! | R10: =IF(Table156[[#This Row],[Rising Through Threshold2]],Table156[[#This Row],[Start time2]],R9) -> #DIV/0! | S10: =IF(AND(Table156[[#This Row],[Rising Through Threshold2]],R9>0),R10-R9,"") -> #DIV/0! | T10: =IF(Table156[[#This Row],[Voltage2]]>Threshold2,1,0) -> #DIV/0! | U10: =AND(Table156[[#This Row],[Last2]]>0,Table156[[#This Row],[Last2]]<MAX(Table156[Last2])) -> #DIV/0! | V10: =OR('Data In'!B16>'Data In'!B15) -> TRUE | W10: =COUNTIF($V$2:V10,"false") -> 1
A11: Start:1112:1.63: | B11: =FIND(":",$A11,1) -> 6 | C11: =FIND(":",$A11,B11+1) -> 11 | D11: =FIND(":",$A11,C11+1) -> 16 | E11: =FIND(":",$A11,D11+1) -> #VALUE! | F11: =IF(Table156[[#This Row],[seq]]>=Table156[[#Totals],[seq]],'Data In'!B17,"") -> 235.44 | G11: ='Data In'!C17 -> 2.53 | H11: =_xlfn.NUMBERVALUE(MID($A11,E11+1,1000)) -> #VALUE! | I11: =AND(G10<Threshold,G11>Threshold) -> TRUE | J11: =IF(Table156[[#This Row],[Rising Through Threshold]],Table156[[#This Row],[Start time]],J10) -> 235.44 | K11: =IF(AND(Table156[[#This Row],[Rising Through Threshold]],J10>0),J11-J10,"") | L11: =IF(Table156[[#This Row],[Voltage]]>Threshold,1,0) -> 1 | M11: =AND(Table156[[#This Row],[Last]]>0,Table156[[#This Row],[Last]]<MAX(Table156[Last])) -> TRUE | N11: ='Data In'!D17 -> a | O11: ='Data In'!E17 -> a | P11: =_xlfn.NUMBERVALUE(MID($A11,K11+1,1000)) -> #VALUE! | Q11: =AND(O10<Threshold2,O11>Threshold2) -> #DIV/0! | R11: =IF(Table156[[#This Row],[Rising Through Threshold2]],Table156[[#This Row],[Start time2]],R10) -> #DIV/0! | S11: =IF(AND(Table156[[#This Row],[Rising Through Threshold2]],R10>0),R11-R10,"") -> #DIV/0! | T11: =IF(Table156[[#This Row],[Voltage2]]>Threshold2,1,0) -> #DIV/0! | U11: =AND(Table156[[#This Row],[Last2]]>0,Table156[[#This Row],[Last2]]<MAX(Table156[Last2])) -> #DIV/0! | V11: =OR('Data In'!B17>'Data In'!B16) -> TRUE | W11: =COUNTIF($V$2:V11,"false") -> 1
A12: Start:1224:1.32: | B12: =FIND(":",$A12,1) -> 6 | C12: =FIND(":",$A12,B12+1) -> 11 | D12: =FIND(":",$A12,C12+1) -> 16 | E12: =FIND(":",$A12,D12+1) -> #VALUE! | F12: =IF(Table156[[#This Row],[seq]]>=Table156[[#Totals],[seq]],'Data In'!B18,"") -> 261.6 | G12: ='Data In'!C18 -> 2.71 | H12: =_xlfn.NUMBERVALUE(MID($A12,E12+1,1000)) -> #VALUE! | I12: =AND(G11<Threshold,G12>Threshold) -> FALSE | J12: =IF(Table156[[#This Row],[Rising Through Threshold]],Table156[[#This Row],[Start time]],J11) -> 235.44 | K12: =IF(AND(Table156[[#This Row],[Rising Through Threshold]],J11>0),J12-J11,"") | L12: =IF(Table156[[#This Row],[Voltage]]>Threshold,1,0) -> 1 | M12: =AND(Table156[[#This Row],[Last]]>0,Table156[[#This Row],[Last]]<MAX(Table156[Last])) -> TRUE | N12: ='Data In'!D18 -> a | O12: ='Data In'!E18 -> a | P12: =_xlfn.NUMBERVALUE(MID($A12,K12+1,1000)) -> #VALUE! | Q12: =AND(O11<Threshold2,O12>Threshold2) -> #DIV/0! | R12: =IF(Table156[[#This Row],[Rising Through Threshold2]],Table156[[#This Row],[Start time2]],R11) -> #DIV/0! | S12: =IF(AND(Table156[[#This Row],[Rising Through Threshold2]],R11>0),R12-R11,"") -> #DIV/0! | T12: =IF(Table156[[#This Row],[Voltage2]]>Threshold2,1,0) -> #DIV/0! | U12: =AND(Table156[[#This Row],[Last2]]>0,Table156[[#This Row],[Last2]]<MAX(Table156[Last2])) -> #DIV/0! | V12: =OR('Data In'!B18>'Data In'!B17) -> TRUE | W12: =COUNTIF($V$2:V12,"false") -> 1
